Workbook

Sheet part(a)
A4: Given Cases of swift shipping | B4: Given Cost | C4: Expected Cost
A5: Strikes happen during the normal ships | B5: 60000 | C5: =B5*B8+(1-B8)*B7 -> 10000
A6: Postepones the shipping pre-empting | B6: 10000 | C6: =B6 -> 10000
A7: Regular scotish shipping run | B7: 4000 | E7: =C5-C6 -> 0
A8: Assume the probility of strikes effect the company | B8: 0.10714286
A9: the strike not occur | B9: =1-B8 -> 0.89285714
A10: For what values of p does Swift minimize expected total cost by postponing shipping?
C11: (EMV) postepones the shipping | D11: (EMV) Strike happen
B12: Probility | C12: =C6 -> 10000 | D12: =C5 -> 10000
B13: 0.11 | C13: 10000 | D13: 10160
B14: 0.12 | C14: 10000 | D14: 10720
B15: 0.13 | C15: 10000 | D15: 11280
B16: 0.14 | C16: 10000 | D16: 11840
B17: 0.15 | C17: 10000 | D17: 12400
B18: 0.16 | C18: 10000 | D18: 12960
B19: 0.17 | C19: 10000 | D19: 13520
B20: 0.18 | C20: 10000 | D20: 14080
B21: 0.19 | C21: 10000 | D21: 14640
B22: 0.2 | C22: 10000 | D22: 15200
B23: 0.21 | C23: 10000 | D23: 15760
B24: 0.22 | C24: 10000 | D24: 16320
... B32: 0.3 | C32: 10000 | D32: 20800
A86: Build a decision tree with trial values of p
C88: =$B$8 -> 0.10714286 | D88: =_xll.PTreeNodeProbability(treeCalc_2!$F$2,4) -> 0.10714286
C89: =$B$5 -> 60000 | D89: =_xll.PTreeNodeValue(treeCalc_2!$F$2,4) -> 120000
B90: =_xll.PTreeNodeDecision(treeCalc_2!$F$2,2) -> TRUE | C90: Chance
B91: =$B$5 -> 60000 | C91: =_xll.PTreeNodeValue(treeCalc_2!$F$2,2) -> 70000
C92: =$B$9 -> 0.89285714 | D92: =_xll.PTreeNodeProbability(treeCalc_2!$F$2,5) -> 0.89285714
C93: =$B$7 -> 4000 | D93: =_xll.PTreeNodeValue(treeCalc_2!$F$2,5) -> 64000
B94: Decision
B95: =_xll.PTreeNodeValue(treeCalc_2!$F$2,1) -> 70000
C96: =$B$8 -> 0.10714286 | D96: =_xll.PTreeNodeProbability(treeCalc_2!$F$2,6) -> 0
C97: =$B$6 -> 10000 | D97: =_xll.PTreeNodeValue(treeCalc_2!$F$2,6) -> 20000
B98: =_xll.PTreeNodeDecision(treeCalc_2!$F$2,3) -> FALSE | C98: Chance
B99: =$B$6 -> 10000 | C99: =_xll.PTreeNodeValue(treeCalc_2!$F$2,3) -> 14642.857
C100: =$B$9 -> 0.89285714 | D100: =_xll.PTreeNodeProbability(treeCalc_2!$F$2,7) -> 0
C101: =$B$7 -> 4000 | D101: =_xll.PTreeNodeValue(treeCalc_2!$F$2,7) -> 14000
A106: Determine the approximate probability p that minimises expected cost.
C107: (EMV) Strike happen | D107: (EMV) postepones the shippping
B108: Probility | C108: =C5 -> 10000 | D108: =C6 -> 10000 | E108: Optimal Decision
...

Sheet part(b.)
A3: Swift pay for Data | B3: 1000
A4: If swift not buy the Data | B4: 0 | I4: Baye's rule calculation
I5: P(predict strike) | J5: P(predict no strike)
B6: probility | I6: =B12*B7+B8*C13 -> 0.24 | J6: =1-I6 -> 0.76
A7: provided probility that effect the shipping | B7: 0.15
A8: The probility that not efect the shipping | B8: =1-B7 -> 0.85
I10: Posterior Probility | J10: Complimantary of Posterior Probility
A11: Different type of prediction | B11: probility | C11: complimentary probility | H11: P(strike | predict strike) | I11: =B7*B12/I6 -> 0.46875 | J11: =1-I11 -> 0.53125
A12: If there will be a strike | B12: 0.75 | C12: =1-B12 -> 0.25 | H12: P(strike | predict no strike) | I12: =C13*B7/J6 -> 0.029605263 | J12: =1-I12 -> 0.97039474
A13: If there will be not a strike | B13: 0.85 | C13: =1-B13 -> 0.15
A21: Expected cost if predict strike | B21: =I11*'part(a)'!B5+J11*'part(a)'!B7 -> 30250
A22: Expected cost if predict no strike | B22: =I12*'part(a)'!B5+J12*'part(a)'!B7 -> 5657.8947
A28: Decision if predict strike | B28: =IF(B21<'part(a)'!B6,"Normal Shipping","Postpone Shipping") -> Postpone Shipping
A29: Decision if predict no strike | B29: =IF(B22<'part(a)'!B6,"Normal Shipping","Postpone Shipping") -> Normal Shipping

Sheet part(c)
A3: Given Probility
A4: Probability of Strike | B4: 0.15
A5: complimentary probility | B5: =1-B4 -> 0.85
A13: EMV for normal shipping(p=15%) also EMV of purchase Data | B13: =B4*'part(b.)'!B21+B5*'part(b.)'!B22 -> 9346.7105
A14: Postpone Shipping | B14: ='part(a)'!B6 -> 10000
A16: (EVI)= | B16: =B13-B34 -> -631.11842
B22: Baye's rule calculation
B23: P(predict strike) | C23: P(predict no strike)
B24: ='part(b.)'!I6 -> 0.24 | C24: =1-B24 -> 0.76 | I24: Chart EVI versus probility
B28: Posterior Probility | C28: Complimantary of Posterior Probility
A29: P(strike | predict strike) | B29: ='part(b.)'!I11 -> 0.46875 | C29: =1-B29 -> 0.53125
A30: P(strike | predict no strike) | B30: ='part(b.)'!I12 -> 0.029605263 | C30: =1-B30 -> 0.97039474
A32: Finding EMV VALUE
A33: EMV with purchase of Data | B33: =B13 -> 9346.7105
A34: Calculate EMV with purchase of data | B34: ='part(b.)'!B3+B24*B38+C24*B42 -> 9977.8289
B36: =B29*'part(b.)'!B21 -> 14179.687
B37: =C29*'part(b.)'!B22 -> 3005.7566
A38: For predictions of a strike: | B38: =B36+B37 -> 17185.444
B40: =B30*'part(b.)'!B21 -> 895.55921
B41: =C30*'part(b.)'!B22 -> 5490.3913
A42: For predictions of no strike: | B42: =B40+B41 -> 6385.9505
A45: EVI(EMV Data purchase - EMV Data not purchase) | B45: =B34-B33 -> 631.11842
G47: Fiding (EVI) value from p =0.05 to.3
H49: in(%) | I49: EMV of normal shipping | J49: EMV of postpone shipping | K49: EVI | M49: Probility | N49: EVI
G50: probility | I50: =B13 -> 9346.7105 | J50: =B14 -> 10000 | K50: =B16 -> -631.11842 | M50: 0.05 | N50: -3090.3289
G51: 0.05 | H51: 0.05 | I51: 6887.5 | J51: 10000 | K51: -3090.3289 | M51: 0.06 | N51: -2844.4079
G52: 0.06 | H52: 0.06 | I52: 7133.4211 | J52: 10000 | K52: -2844.4079 | M52: 0.07 | N52: -2598.4868
G53: 0.07 | H53: 0.07 | I53: 7379.3421 | J53: 10000 | K53: -2598.4868 | M53: 0.08 | N53: -2352.5658
G54: 0.08 | H54: 0.08 | I54: 7625.2632 | J54: 10000 | K54: -2352.5658 | M54: 0.09 | N54: -2106.6447
G55: 0.09 | H55: 0.09 | I55: 7871.1842 | J55: 10000 | K55: -2106.6447 | M55: 0.1 | N55: -1860.7237
G56: 0.1 | H56: 0.1 | I56: 8117.1053 | J56: 10000 | K56: -1860.7237 | M56: 0.11 | N56: -1614.8026
G57: 0.11 | H57: 0.11 | I57: 8363.0263 | J57: 10000 | K57: -1614.8026 | M57: 0.12 | N57: -1368.8816
G58: 0.12 | H58: 0.12 | I58: 8608.9474 | J58: 10000 | K58: -1368.8816 | M58: 0.13 | N58: -1122.9605
G59: 0.13 | H59: 0.13 | I59: 8854.8684 | J59: 10000 | K59: -1122.9605 | M59: 0.14 | N59: -877.03947
G60: 0.14 | H60: 0.14 | I60: 9100.7895 | J60: 10000 | K60: -877.03947 | M60: 0.15 | N60: -631.11842
G61: 0.15 | H61: 0.15 | I61: 9346.7105 | J61: 10000 | K61: -631.11842 | M61: 0.16 | N61: -385.19737
G62: 0.16 | H62: 0.16 | I62: 9592.6316 | J62: 10000 | K62: -385.19737 | M62: 0.17 | N62: -139.27632
... G75: 0.29 | H75: 0.29 | I75: 12789.605 | J75: 10000 | K75: 2811.7763 | M75: 0.3 | N75: 3057.6974
G76: 0.3 | H76: 0.3 | I76: 13035.526 | J76: 10000 | K76: 3057.6974

Sheet treeCalc_2
A1: Name | B1: decision | E1: Ptree1 Compatibility | F1: 3 | H1: Output Label | K1: R-Value Ref. | L1: 100
A2: SheetRef | B2: ='part(a)'!#REF! -> #REF! | E2: Eval. Function | F2: =_xll.PTreeEvaluate5(B3,$L$11:$L$17,$J$11:$J$17,$K$11:$K$17,$N$11:$N$17,$G$11:$G$17,,L1) -> 5891714
A3: GenInfo | B3: 0,2,1,0,0,Exponential, 0,0,-1,0,-1,-1,.0001 | E3: Creation Version | F3: 8.2.2 | H3: Output Value NF | I3: <NF>
A4: Def. Link | B4: = | E4: Required Version | F4: 5.0.0 | H4: Output Prob NF | I4: Automatic
A5: EXT REFS | B5: 0 | E5: Recommended Version | F5: 5.0.0 | H5: Input Value NF | I5: <NF>
A6: Def. Form | E6: Last Modified By Version | F6: 8.2.2 | H6: Input Prob NF | I6: Automatic
A7: Calc Macro | E7: Model GUID | F7: 22802464
A8: Highest# | B8: 7
A10: Anchor Cell | B10: Branch Name | C10: bformtype | D10: valformula | E10: pbformula | F10: distribution | G10: cumPayoffFunction | H10: link | I10: ENDNODEFORMULA | J10: VAL | K10: PB | L10: GenInfo | M10: IntRefs | N10: RefRefs | O10: NodeNames | P10: Collapsed
A11: ='part(a)'!$B$95 -> 70000 | B11: =B1 -> decision | C11: 0 | I11: DEFAULT | J11: ='part(a)'!$A$95 -> 0 | K11: ='part(a)'!$A$94 -> 0 | L11: 2,0,0,2,2,3,0,0,0 | M11: 0 | O11: ='part(a)'!$B$94 -> Decision | P11: FALSE
A12: ='part(a)'!$C$91 -> 70000 | B12: ship as usual | C12: 0 | I12: DEFAULT | J12: ='part(a)'!$B$91 -> 60000 | L12: 1,0,0,2,4,5,1,0,0 | M12: 0 | O12: ='part(a)'!$C$90 -> Chance | P12: FALSE
A13: ='part(a)'!$C$99 -> 14642.857 | B13: postpones the ship | C13: 0 | I13: DEFAULT | J13: ='part(a)'!$B$99 -> 10000 | L13: 1,0,0,2,6,7,1,0,0 | M13: 0 | O13: ='part(a)'!$C$98 -> Chance | P13: FALSE
A14: ='part(a)'!$D$89 -> 120000 | B14: strike occur | C14: 0 | H14: DEFAULT | I14: DEFAULT | J14: ='part(a)'!$C$89 -> 60000 | K14: ='part(a)'!$C$88 -> 0.10714286 | L14: 4,0,0,0,2,0,0 | M14: 0 | P14: FALSE
A15: ='part(a)'!$D$93 -> 64000 | B15: strike not occur | C15: 0 | H15: DEFAULT | I15: DEFAULT | J15: ='part(a)'!$C$93 -> 4000 | K15: ='part(a)'!$C$92 -> 0.89285714 | L15: 4,0,0,0,2,0,0 | M15: 0 | P15: FALSE
A16: ='part(a)'!$D$97 -> 20000 | B16: strike occur | C16: 0 | H16: DEFAULT | I16: DEFAULT | J16: ='part(a)'!$C$97 -> 10000 | K16: ='part(a)'!$C$96 -> 0.10714286 | L16: 4,0,0,0,3,0,0 | M16: 0 | P16: FALSE
A17: ='part(a)'!$D$101 -> 14000 | B17: strike not occur | C17: 0 | H17: DEFAULT | I17: DEFAULT | J17: ='part(a)'!$C$101 -> 4000 | K17: ='part(a)'!$C$100 -> 0.89285714 | L17: 4,0,0,0,3,0,0 | M17: 0 | P17: FALSE

Sheet _PalUtilTempWorksheet

Sheet treeCalc_1
A1: Name | B1: Ship as usual or Postpone | E1: Ptree1 Compatibility | F1: 3 | H1: Output Label | K1: R-Value Ref. | L1: 100
A2: SheetRef | B2: ='part(a)'!#REF! -> #REF! | E2: Eval. Function | F2: =_xll.PTreeEvaluate5(B3,$L$11:$L$17,$J$11:$J$17,$K$11:$K$17,$N$11:$N$17,$G$11:$G$17,,L1) -> 2752897
A3: GenInfo | B3: 0,1,1,0,0,Exponential, 0,0,-1,0,-1,-1,.0001 | E3: Creation Version | F3: 8.2.2 | H3: Output Value NF | I3: <NF>
A4: Def. Link | B4: = | E4: Required Version | F4: 5.0.0 | H4: Output Prob NF | I4: Automatic
A5: EXT REFS | B5: 0 | E5: Recommended Version | F5: 5.0.0 | H5: Input Value NF | I5: <NF>
A6: Def. Form | E6: Last Modified By Version | F6: 8.2.2 | H6: Input Prob NF | I6: Automatic
A7: Calc Macro | E7: Model GUID | F7: 21210897
A8: Highest# | B8: 7
A10: Anchor Cell | B10: Branch Name | C10: bformtype | D10: valformula | E10: pbformula | F10: distribution | G10: cumPayoffFunction | H10: link | I10: ENDNODEFORMULA | J10: VAL | K10: PB | L10: GenInfo | M10: IntRefs | N10: RefRefs | O10: NodeNames | P10: Collapsed
A11: =#REF! -> #REF! | B11: =B1 -> Ship as usual or Postpone | C11: 0 | I11: DEFAULT | J11: =#REF! -> #REF! | K11: =#REF! -> #REF! | L11: 2,0,0,2,2,3,0,0,0 | M11: 0 | O11: =#REF! -> #REF! | P11: FALSE
A12: =#REF! -> #REF! | B12: Ship as usual | C12: 0 | I12: DEFAULT | J12: =#REF! -> #REF! | L12: 1,0,0,2,4,5,1,0,0 | M12: 0 | O12: =#REF! -> #REF! | P12: FALSE
A13: =#REF! -> #REF! | B13: Postpone shipping | C13: 0 | I13: DEFAULT | J13: =#REF! -> #REF! | L13: 1,0,0,2,6,7,1,0,0 | M13: 0 | O13: =#REF! -> #REF! | P13: FALSE
A14: =#REF! -> #REF! | B14: strike occur | C14: 0 | H14: DEFAULT | I14: DEFAULT | J14: =#REF! -> #REF! | K14: =#REF! -> #REF! | L14: 4,0,0,0,2,0,0 | M14: 0 | P14: FALSE
A15: =#REF! -> #REF! | B15: strike not occur | C15: 0 | H15: DEFAULT | I15: DEFAULT | J15: =#REF! -> #REF! | K15: =#REF! -> #REF! | L15: 4,0,0,0,2,0,0 | M15: 0 | P15: FALSE
A16: =#REF! -> #REF! | B16: strike occur | C16: 0 | H16: DEFAULT | I16: DEFAULT | J16: =#REF! -> #REF! | K16: =#REF! -> #REF! | L16: 4,0,0,0,3,0,0 | M16: 0 | P16: FALSE
A17: =#REF! -> #REF! | B17: strike not occur | C17: 0 | H17: DEFAULT | I17: DEFAULT | J17: =#REF! -> #REF! | K17: =#REF! -> #REF! | L17: 4,0,0,0,3,0,0 | M17: 0 | P17: FALSE
