Workbook
Name ST_Afterorbeforeholiday: #REF!
Name ST_Afterorbeforeholiday_6: 'Dummy variable'!$F$2:$F$255
Name ST_AfterorbeforeholidayDummyVariable: #REF!
Name ST_AfterorbeforeholidayNo: 'Dummy variable'!$AC$2:$AC$255
Name ST_AfterorbeforeholidayYes: 'Dummy variable'!$AD$2:$AD$255
Name ST_Arrivals: #REF!
Name ST_Arrivals_7: 'Dummy variable'!$G$2:$G$255
Name ST_Dayofmonth: #REF!
Name ST_Dayofmonth_2: 'Dummy variable'!$B$2:$B$255
Name ST_Dayofweek: #REF!
Name ST_Dayofweek_3: 'Dummy variable'!$C$2:$C$255
Name ST_DayofweekFri: 'Dummy variable'!$T$2:$T$255
Name ST_DayofweekMon: 'Dummy variable'!$U$2:$U$255
Name ST_DayofweekThu: 'Dummy variable'!$V$2:$V$255
Name ST_DayofweekTue: 'Dummy variable'!$W$2:$W$255
Name ST_DayofweekWed: 'Dummy variable'!$X$2:$X$255
Name ST_Facultypayday: #REF!
Name ST_Facultypayday_5: 'Dummy variable'!$E$2:$E$255
Name ST_FacultypaydayDummyVariable: #REF!
Name ST_FacultypaydayNo: 'Dummy variable'!$AA$2:$AA$255
Name ST_FacultypaydayYes: 'Dummy variable'!$AB$2:$AB$255
Name ST_FirstDayofMonth: #REF!
Name ST_fri: #REF!
Name ST_mon: #REF!
Name ST_Month: #REF!
Name ST_Month_1: 'Dummy variable'!$A$2:$A$255
Name ST_MonthApr: 'Dummy variable'!$H$2:$H$255
Name ST_MonthAug: 'Dummy variable'!$I$2:$I$255
Name ST_MonthDec: 'Dummy variable'!$J$2:$J$255
Name ST_MonthFeb: 'Dummy variable'!$K$2:$K$255
Name ST_MonthJan: 'Dummy variable'!$L$2:$L$255
Name ST_MonthJul: 'Dummy variable'!$M$2:$M$255
Name ST_MonthJun: 'Dummy variable'!$N$2:$N$255
Name ST_MonthMar: 'Dummy variable'!$O$2:$O$255
Name ST_MonthMay: 'Dummy variable'!$P$2:$P$255
Name ST_MonthNov: 'Dummy variable'!$Q$2:$Q$255
Name ST_MonthOct: 'Dummy variable'!$R$2:$R$255
Name ST_MonthSep: 'Dummy variable'!$S$2:$S$255
Name ST_OutlierRegression: #REF!
Name ST_OutlierRegression2: #REF!
Name ST_OutlierRegression3: #REF!
Name ST_OutlierRegression4: #REF!
Name ST_Staffpayday: #REF!
Name ST_Staffpayday_4: 'Dummy variable'!$D$2:$D$255
Name ST_StaffpaydayDummyVariable: #REF!
Name ST_StaffpaydayNo: 'Dummy variable'!$Y$2:$Y$255
Name ST_StaffpaydayYes: 'Dummy variable'!$Z$2:$Z$255
Name ST_thu: #REF!
Name ST_tue: #REF!
Name ST_wed: #REF!
Name StatToolsHeader: 'Regression(a.)'!$1:$6
Name StatToolsHeader: 'Regression(b..)'!$1:$6
Name STWBD_StatToolsDataViewer8_DataSet: "DS:DG72E9BAD"

Sheet Dataset
A1: Month | B1: Day of month | C1: Day of week | D1: Staff payday | E1: Faculty payday | F1: After or before holiday | G1: Arrivals
A2: Jan | B2: 2 | C2: Tue | D2: Yes | E2: Yes | F2: Yes | G2: 1825
A3: Jan | B3: 3 | C3: Wed | D3: No | E3: No | F3: No | G3: 1257
A4: Jan | B4: 4 | C4: Thu | D4: No | E4: No | F4: No | G4: 969
A5: Jan | B5: 5 | C5: Fri | D5: Yes | E5: No | F5: No | G5: 1672
A6: Jan | B6: 8 | C6: Mon | D6: No | E6: No | F6: No | G6: 1098
A7: Jan | B7: 9 | C7: Tue | D7: No | E7: No | F7: No | G7: 691
A8: Jan | B8: 10 | C8: Wed | D8: No | E8: No | F8: No | G8: 672
A9: Jan | B9: 11 | C9: Thu | D9: No | E9: No | F9: No | G9: 754
A10: Jan | B10: 12 | C10: Fri | D10: No | E10: No | F10: No | G10: 972
A11: Jan | B11: 15 | C11: Mon | D11: No | E11: No | F11: No | G11: 816
A12: Jan | B12: 16 | C12: Tue | D12: No | E12: No | F12: No | G12: 717
A13: Jan | B13: 17 | C13: Wed | D13: No | E13: No | F13: No | G13: 728
... A255: Dec | B255: 31 | C255: Mon | D255: No | E255: No | F255: No | G255: 1146

Sheet Dummy variable
A1: Month | B1: Day of month | C1: Day of week | D1: Staff payday | E1: Faculty payday | F1: After or before holiday | G1: Arrivals | H1: Month = Apr | I1: Month = Aug | J1: Month = Dec | K1: Month = Feb | L1: Month = Jan | M1: Month = Jul | N1: Month = Jun | O1: Month = Mar | P1: Month = May | Q1: Month = Nov | R1: Month = Oct | S1: Month = Sep | T1: Day of week = Fri | U1: Day of week = Mon | V1: Day of week = Thu | W1: Day of week = Tue | X1: Day of week = Wed | Y1: Staff payday = No | Z1: Staff payday = Yes | AA1: Faculty payday = No | AB1: Faculty payday = Yes | AC1: After or before holiday = No | AD1: After or before holiday = Yes
A2: Jan | B2: 2 | C2: Tue | D2: Yes | E2: Yes | F2: Yes | G2: 1825 | H2: 0 | I2: 0 | J2: 0 | K2: 0 | L2: 1 | M2: 0 | N2: 0 | O2: 0 | P2: 0 | Q2: 0 | R2: 0 | S2: 0 | T2: 0 | U2: 0 | V2: 0 | W2: 1 | X2: 0 | Y2: 0 | Z2: 1 | AA2: 0 | AB2: 1 | AC2: 0 | AD2: 1
A3: Jan | B3: 3 | C3: Wed | D3: No | E3: No | F3: No | G3: 1257 | H3: 0 | I3: 0 | J3: 0 | K3: 0 | L3: 1 | M3: 0 | N3: 0 | O3: 0 | P3: 0 | Q3: 0 | R3: 0 | S3: 0 | T3: 0 | U3: 0 | V3: 0 | W3: 0 | X3: 1 | Y3: 1 | Z3: 0 | AA3: 1 | AB3: 0 | AC3: 1 | AD3: 0
A4: Jan | B4: 4 | C4: Thu | D4: No | E4: No | F4: No | G4: 969 | H4: 0 | I4: 0 | J4: 0 | K4: 0 | L4: 1 | M4: 0 | N4: 0 | O4: 0 | P4: 0 | Q4: 0 | R4: 0 | S4: 0 | T4: 0 | U4: 0 | V4: 1 | W4: 0 | X4: 0 | Y4: 1 | Z4: 0 | AA4: 1 | AB4: 0 | AC4: 1 | AD4: 0
A5: Jan | B5: 5 | C5: Fri | D5: Yes | E5: No | F5: No | G5: 1672 | H5: 0 | I5: 0 | J5: 0 | K5: 0 | L5: 1 | M5: 0 | N5: 0 | O5: 0 | P5: 0 | Q5: 0 | R5: 0 | S5: 0 | T5: 1 | U5: 0 | V5: 0 | W5: 0 | X5: 0 | Y5: 0 | Z5: 1 | AA5: 1 | AB5: 0 | AC5: 1 | AD5: 0
A6: Jan | B6: 8 | C6: Mon | D6: No | E6: No | F6: No | G6: 1098 | H6: 0 | I6: 0 | J6: 0 | K6: 0 | L6: 1 | M6: 0 | N6: 0 | O6: 0 | P6: 0 | Q6: 0 | R6: 0 | S6: 0 | T6: 0 | U6: 1 | V6: 0 | W6: 0 | X6: 0 | Y6: 1 | Z6: 0 | AA6: 1 | AB6: 0 | AC6: 1 | AD6: 0
A7: Jan | B7: 9 | C7: Tue | D7: No | E7: No | F7: No | G7: 691 | H7: 0 | I7: 0 | J7: 0 | K7: 0 | L7: 1 | M7: 0 | N7: 0 | O7: 0 | P7: 0 | Q7: 0 | R7: 0 | S7: 0 | T7: 0 | U7: 0 | V7: 0 | W7: 1 | X7: 0 | Y7: 1 | Z7: 0 | AA7: 1 | AB7: 0 | AC7: 1 | AD7: 0
A8: Jan | B8: 10 | C8: Wed | D8: No | E8: No | F8: No | G8: 672 | H8: 0 | I8: 0 | J8: 0 | K8: 0 | L8: 1 | M8: 0 | N8: 0 | O8: 0 | P8: 0 | Q8: 0 | R8: 0 | S8: 0 | T8: 0 | U8: 0 | V8: 0 | W8: 0 | X8: 1 | Y8: 1 | Z8: 0 | AA8: 1 | AB8: 0 | AC8: 1 | AD8: 0
A9: Jan | B9: 11 | C9: Thu | D9: No | E9: No | F9: No | G9: 754 | H9: 0 | I9: 0 | J9: 0 | K9: 0 | L9: 1 | M9: 0 | N9: 0 | O9: 0 | P9: 0 | Q9: 0 | R9: 0 | S9: 0 | T9: 0 | U9: 0 | V9: 1 | W9: 0 | X9: 0 | Y9: 1 | Z9: 0 | AA9: 1 | AB9: 0 | AC9: 1 | AD9: 0
A10: Jan | B10: 12 | C10: Fri | D10: No | E10: No | F10: No | G10: 972 | H10: 0 | I10: 0 | J10: 0 | K10: 0 | L10: 1 | M10: 0 | N10: 0 | O10: 0 | P10: 0 | Q10: 0 | R10: 0 | S10: 0 | T10: 1 | U10: 0 | V10: 0 | W10: 0 | X10: 0 | Y10: 1 | Z10: 0 | AA10: 1 | AB10: 0 | AC10: 1 | AD10: 0
A11: Jan | B11: 15 | C11: Mon | D11: No | E11: No | F11: No | G11: 816 | H11: 0 | I11: 0 | J11: 0 | K11: 0 | L11: 1 | M11: 0 | N11: 0 | O11: 0 | P11: 0 | Q11: 0 | R11: 0 | S11: 0 | T11: 0 | U11: 1 | V11: 0 | W11: 0 | X11: 0 | Y11: 1 | Z11: 0 | AA11: 1 | AB11: 0 | AC11: 1 | AD11: 0
A12: Jan | B12: 16 | C12: Tue | D12: No | E12: No | F12: No | G12: 717 | H12: 0 | I12: 0 | J12: 0 | K12: 0 | L12: 1 | M12: 0 | N12: 0 | O12: 0 | P12: 0 | Q12: 0 | R12: 0 | S12: 0 | T12: 0 | U12: 0 | V12: 0 | W12: 1 | X12: 0 | Y12: 1 | Z12: 0 | AA12: 1 | AB12: 0 | AC12: 1 | AD12: 0
A13: Jan | B13: 17 | C13: Wed | D13: No | E13: No | F13: No | G13: 728 | H13: 0 | I13: 0 | J13: 0 | K13: 0 | L13: 1 | M13: 0 | N13: 0 | O13: 0 | P13: 0 | Q13: 0 | R13: 0 | S13: 0 | T13: 0 | U13: 0 | V13: 0 | W13: 0 | X13: 1 | Y13: 1 | Z13: 0 | AA13: 1 | AB13: 0 | AC13: 1 | AD13: 0
... A255: Dec | B255: 31 | C255: Mon | D255: No | E255: No | F255: No | G255: 1146 | H255: 0 | I255: 0 | J255: 1 | K255: 0 | L255: 0 | M255: 0 | N255: 0 | O255: 0 | P255: 0 | Q255: 0 | R255: 0 | S255: 0 | T255: 0 | U255: 1 | V255: 0 | W255: 0 | X255: 0 | Y255: 1 | Z255: 0 | AA255: 1 | AB255: 0 | AC255: 1 | AD255: 0

Sheet _PalUtilTempWorksheet
B9: =1 -> 1

Sheet _STDS_DG2755809F
A1: Name | B1: Data Set #1 | C1: StatTools Version that generated sheet, Major | D1: 8 | E1: StatTools Version that generated sheet, Minor | F1: 2 | G1: StatTools Version that generated sheet, Revision | H1: 2 | I1: Min. StatTools Version to Read Sheet, Major (note ST versions before 1.1.1 don't perform forward compatibility check) | J1: 1 | K1: Min. StatTools Version to Read Sheet, Minor | L1: 0 | M1: Min. StatTools Version to Read Sheet, Revision | N1: 0 | O1: Min. StatTools version to not put up warning about extra info, Major | P1: 1 | Q1: Min. StatTools version to not put up warning about extra info, Minor | R1: 0 | S1: Min. StatTools version to not put up warning about extra info, Revision | T1: 0
A2: GUID | B2: DG2755809F
A3: Format Range | B3: =IF(B10>256,"TripUpST110AndEarlier",TRUE) -> TRUE
A4: Variable Layout | B4: Columns
A5: Variable Names In Cells | B5: TRUE
A6: Variable Names In 2nd Cells | B6: FALSE
A7: Data Set Ranges | B7: =#REF! -> #REF!
A8: Data Sheet Format | B8: 2
A9: Formula Eval Cell | B9: =1 -> 1
A10: Num Stored Vars | B10: 20
A12: 1 : Info | B12: VG1EE1DA12C7E1AE8 | C12: var1 | D12: ST_Month | E12: TRUE | F12: 0 | G12: 4 | H12: 1
A13: 1 : Ranges | B13: =#REF! -> #REF!
A14: 1 : MultiRefs
A15: 2 : Info | B15: VG30581D3B7C0557 | C15: var2 | D15: ST_Dayofmonth | E15: TRUE | F15: 0 | G15: 4 | H15: 0
A16: 2 : Ranges | B16: =#REF! -> #REF!
A17: 2 : MultiRefs
A18: 3 : Info | B18: VG35E4E0D1302409B5 | C18: var3 | D18: ST_Dayofweek | E18: TRUE | F18: 0 | G18: 4 | H18: 1
A19: 3 : Ranges | B19: =#REF! -> #REF!
A20: 3 : MultiRefs
A21: 4 : Info | B21: VG332B2D362EF6B65B | C21: var4 | D21: ST_mon | E21: TRUE | F21: 0 | G21: 4 | H21: 1
A22: 4 : Ranges | B22: =#REF! -> #REF!
A23: 4 : MultiRefs
A24: 5 : Info | B24: VG29A19E7360BC12A | C24: var5 | D24: ST_tue | E24: TRUE | F24: 0 | G24: 4 | H24: 1
A25: 5 : Ranges | B25: =#REF! -> #REF!
A26: 5 : MultiRefs
A27: 6 : Info | B27: VGB48D8661AC3CDC9 | C27: var6 | D27: ST_wed | E27: TRUE | F27: 0 | G27: 4 | H27: 1
A28: 6 : Ranges | B28: =#REF! -> #REF!
A29: 6 : MultiRefs
A30: 7 : Info | B30: VG16F3EEB215554385 | C30: var7 | D30: ST_thu | E30: TRUE | F30: 0 | G30: 4 | H30: 1
A31: 7 : Ranges | B31: =#REF! -> #REF!
A32: 7 : MultiRefs
A33: 8 : Info | B33: VG379F76084AAB65 | C33: var8 | D33: ST_fri | E33: TRUE | F33: 0 | G33: 4 | H33: 1
A34: 8 : Ranges | B34: =#REF! -> #REF!
A35: 8 : MultiRefs
A36: 9 : Info | B36: VGB2A6A953089C968 | C36: var9 | D36: ST_Staffpayday | E36: TRUE | F36: 0 | G36: 4 | H36: 1
A37: 9 : Ranges | B37: =#REF! -> #REF!
A38: 9 : MultiRefs
A39: 10 : Info | B39: VG29E57C0DEC13DA | C39: var10 | D39: ST_StaffpaydayDummyVariable | E39: TRUE | F39: 0 | G39: 4 | H39: 1
A40: 10 : Ranges | B40: =#REF! -> #REF!
A41: 10 : MultiRefs
...

Sheet _STDS_DGAE5F441
A1: Name | B1: Data Set #2 | C1: StatTools Version that generated sheet, Major | D1: 8 | E1: StatTools Version that generated sheet, Minor | F1: 2 | G1: StatTools Version that generated sheet, Revision | H1: 2 | I1: Min. StatTools Version to Read Sheet, Major (note ST versions before 1.1.1 don't perform forward compatibility check) | J1: 1 | K1: Min. StatTools Version to Read Sheet, Minor | L1: 0 | M1: Min. StatTools Version to Read Sheet, Revision | N1: 0 | O1: Min. StatTools version to not put up warning about extra info, Major | P1: 1 | Q1: Min. StatTools version to not put up warning about extra info, Minor | R1: 0 | S1: Min. StatTools version to not put up warning about extra info, Revision | T1: 0
A2: GUID | B2: DGAE5F441
A3: Format Range | B3: =IF(B10>256,"TripUpST110AndEarlier",TRUE) -> TRUE
A4: Variable Layout | B4: Columns
A5: Variable Names In Cells | B5: TRUE
A6: Variable Names In 2nd Cells | B6: FALSE
A7: Data Set Ranges | B7: ='Dummy variable'!$A$1:$AD$255 -> 9
A8: Data Sheet Format | B8: 2
A9: Formula Eval Cell | B9: =1 -> 1
A10: Num Stored Vars | B10: 30
A12: 1 : Info | B12: VG32C17536165CAF31 | C12: var1 | D12: ST_Month_1 | E12: TRUE | F12: 1 | G12: 2 | H12: 1
A13: 1 : Ranges | B13: ='Dummy variable'!$A$1:$A$255 -> Jan
A14: 1 : MultiRefs
A15: 2 : Info | B15: VG3963B8CB204F64E4 | C15: var2 | D15: ST_Dayofmonth_2 | E15: TRUE | F15: 1 | G15: 3 | H15: 0
A16: 2 : Ranges | B16: ='Dummy variable'!$B$1:$B$255 -> 22
A17: 2 : MultiRefs
A18: 3 : Info | B18: VG9F016EA14A6BFFA | C18: var3 | D18: ST_Dayofweek_3 | E18: TRUE | F18: 1 | G18: 2 | H18: 1
A19: 3 : Ranges | B19: ='Dummy variable'!$C$1:$C$255 -> Thu
A20: 3 : MultiRefs
A21: 4 : Info | B21: VG13DC253A11E960AB | C21: var4 | D21: ST_Staffpayday_4 | E21: TRUE | F21: 1 | G21: 2 | H21: 1
A22: 4 : Ranges | B22: ='Dummy variable'!$D$1:$D$255 -> No
A23: 4 : MultiRefs
A24: 5 : Info | B24: VG1004D28E290D0F34 | C24: var5 | D24: ST_Facultypayday_5 | E24: TRUE | F24: 1 | G24: 2 | H24: 1
A25: 5 : Ranges | B25: ='Dummy variable'!$E$1:$E$255 -> No
A26: 5 : MultiRefs
A27: 6 : Info | B27: VGC67982D2F75761A | C27: var6 | D27: ST_Afterorbeforeholiday_6 | E27: TRUE | F27: 1 | G27: 2 | H27: 1
A28: 6 : Ranges | B28: ='Dummy variable'!$F$1:$F$255 -> No
A29: 6 : MultiRefs
A30: 7 : Info | B30: VG1F3A8CA42F64C0C5 | C30: var7 | D30: ST_Arrivals_7 | E30: TRUE | F30: 1 | G30: 2 | H30: 0
A31: 7 : Ranges | B31: ='Dummy variable'!$G$1:$G$255 -> 881
A32: 7 : MultiRefs
A33: 8 : Info | B33: VG3AC34C45208136E4 | C33: Month = Apr | D33: ST_MonthApr | E33: TRUE | F33: 1 | G33: 4 | H33: 0
A34: 8 : Ranges | B34: ='Dummy variable'!$H$1:$H$255 -> 0
A35: 8 : MultiRefs
A36: 9 : Info | B36: VG164C35778A33457 | C36: Month = Aug | D36: ST_MonthAug | E36: TRUE | F36: 1 | G36: 4 | H36: 0
A37: 9 : Ranges | B37: ='Dummy variable'!$I$1:$I$255 -> 0
A38: 9 : MultiRefs
A39: 10 : Info | B39: VG1BA42C681999799C | C39: Month = Dec | D39: ST_MonthDec | E39: TRUE | F39: 1 | G39: 4 | H39: 0
A40: 10 : Ranges | B40: ='Dummy variable'!$J$1:$J$255 -> 0
A41: 10 : MultiRefs
...

Sheet Regression(a.)
A1: StatTools Report
A2: Analysis: | B2: Regression
A3: Performed By: | B3: Baljit singh
A4: Date: | B4: 45421
A5: Updating: | B5: Static
A6: Variable: | B6: Arrivals
A8: Linearly dependent variables ignored: Month = Sep, Day of week = Wed, Staff payday = Yes, Faculty payday = Yes, After or before holiday = Yes
A10: Multiple Regression for Arrivals | B10: Multiple_x000D_ R | C10: R-Square | D10: Adjusted_x000D_ R-square | E10: Std. Err. of_x000D_ Estimate | F10: Rows_x000D_ Ignored | G10: Outliers
A11: Summary
B12: 0.90593177 | C12: 0.82071237 | D12: 0.80615483 | E12: 150.19165 | F12: 0 | G12: 2
B14: Degrees of_x000D_ Freedom | C14: Sum of_x000D_ Squares | D14: Mean of_x000D_ Squares | E14: F | F14: p-Value
A15: ANOVA Table
A16: Explained | B16: 19 | C16: 24162847 | D16: 1271728.8 | E16: 56.377125 | F16: 3.9085754e-76
A17: Unexplained | B17: 234 | C17: 5278462.5 | D17: 22557.532
B19: Coefficient | C19: Standard_x000D_ Error | D19: t-Value | E19: p-Value | F19: Confidence Interval 95% | H19: Multicollinearity Checking
A20: Regression Table | F20: Lower | G20: Upper | H20: VIF | I20: R-Square
A21: Constant | B21: 1867.99 | C21: 81.581568 | D21: 22.897207 | E21: 1.1330154e-61 | F21: 1707.2618 | G21: 2028.7183
A22: Day of month | B22: -8.8032394 | C22: 1.0894739 | D22: -8.0802665 | E22: 3.4393178e-14 | F22: -10.94967 | G22: -6.6568085 | H22: 1.0227922 | I22: 0.022284302
A23: Month = Apr | B23: 80.130648 | C23: 47.662793 | D23: 1.6811992 | E23: 0.094058414 | F23: -13.772377 | G23: 174.03367 | H23: 1.940032 | I23: 0.48454459
A24: Month = Aug | B24: 118.55063 | C24: 46.631616 | D24: 2.5422801 | E24: 0.011659249 | F24: 26.679181 | G24: 210.42208 | H24: 2.0163942 | I24: 0.50406523
A25: Month = Dec | B25: 137.35446 | C25: 48.240492 | D25: 2.8472857 | E25: 0.0048013075 | F25: 42.313281 | G25: 232.39564 | H25: 1.9008332 | I25: 0.47391491
A26: Month = Feb | B26: 2.1625997 | C26: 48.294731 | D26: 0.044779205 | E26: 0.96432149 | F26: -92.98544 | G26: 97.31064 | H26: 1.90511 | I26: 0.47509593
A27: Month = Jan | B27: -18.347367 | C27: 47.139478 | D27: -0.38921447 | E27: 0.69747146 | F27: -111.21938 | G27: 74.524647 | H27: 1.9794972 | I27: 0.49482122
A28: Month = Jul | B28: 203.17453 | C28: 47.660506 | D28: 4.2629538 | E28: 2.9271981e-05 | F28: 109.27601 | G28: 297.07305 | H28: 1.9398458 | I28: 0.48449512
A29: Month = Jun | B29: 218.60594 | C29: 48.221158 | D29: 4.5334031 | E29: 9.2659631e-06 | F29: 123.60286 | G29: 313.60903 | H29: 1.8993099 | I29: 0.47349296
A30: Month = Mar | B30: 52.162002 | C30: 47.371116 | D30: 1.1011352 | E30: 0.27196921 | F30: -41.166375 | G30: 145.49038 | H30: 1.9989991 | I30: 0.49974965
A31: Month = May | B31: 169.36257 | C31: 47.371543 | D31: 3.5751964 | E31: 0.00042505736 | F31: 76.033351 | G31: 262.69179 | H31: 1.9990351 | I31: 0.49975867
A32: Month = Nov | B32: 39.753497 | C32: 47.963677 | D32: 0.82882504 | E32: 0.40804803 | F32: -54.742317 | G32: 134.24931 | H32: 1.9646033 | I32: 0.49099138
A33: Month = Oct | B33: 32.754073 | C33: 46.741018 | D33: 0.70075652 | E33: 0.48415119 | F33: -59.332914 | G33: 124.84106 | H33: 2.0258667 | I33: 0.5063841
... A40: After or before holiday = No | B40: -275.34178 | C40: 48.289 | D40: -5.7019565 | E40: 3.5536105e-08 | F40: -370.47853 | G40: -180.20503 | H40: 1.0878527 | I40: 0.080757894
A43: Correlation Matrix | B43: Arrivals | C43: Day of month | D43: Month = Apr | E43: Month = Aug | F43: Month = Dec | G43: Month = Feb | H43: Month = Jan | I43: Month = Jul | J43: Month = Jun | K43: Month = Mar | L43: Month = May | M43: Month = Nov | N43: Month = Oct | O43: Day of week = Fri | P43: Day of week = Mon | Q43: Day of week = Thu | R43: Day of week = Tue | S43: Staff payday = No | T43: Faculty payday = No | U43: After or before holiday = No
A44: Arrivals | B44: 1 | C44: -0.25239861 | D44: -0.021275114 | E44: 0.038294619 | F44: 0.055766305 | G44: -0.071408308 | H44: -0.096870197 | I44: 0.10058122 | J44: 0.11050892 | K44: -0.007900887 | L44: 0.065774253 | M44: -0.014934554 | N44: -0.07070768 | O44: 0.68760351 | P44: 0.081013603 | Q44: -0.22290995 | R44: -0.24129838 | S44: -0.64806542 | T44: -0.34547262 | U44: -0.22158964
A45: Day of month | B45: -0.25239861 | C45: 1 | D45: -0.020337491 | E45: 0.018652682 | F45: -0.0010262712 | G45: -0.037787832 | H45: 0.017159801 | I45: 0.023786049 | J45: 0.0023156889 | K45: 0.0075593837 | L45: -0.01324152 | M45: -0.0023612335 | N45: -0.006439837 | O45: 0.0008958046 | P45: 0.0061851446 | Q45: -0.029621542 | R45: -0.013892977 | S45: 0.044973011 | T45: 0.11410604 | U45: -0.041704908
A46: Month = Apr | B46: -0.021275114 | C46: -0.020337491 | D46: 1 | E46: -0.094730453 | F46: -0.087768516 | G46: -0.087768516 | H46: -0.092448322 | I46: -0.090128755 | J46: -0.087768516 | K46: -0.092448322 | L46: -0.092448322 | M46: -0.090128755 | N46: -0.094730453 | O46: -0.010601044 | P46: 0.031141174 | Q46: -0.0077275527 | R46: -0.0077275527 | S46: 0.0032119854 | T46: 0.060776652 | U46: 0.063874115
A47: Month = Aug | B47: 0.038294619 | C47: 0.018652682 | D47: -0.094730453 | E47: 1 | F47: -0.092249707 | G47: -0.092249707 | H47: -0.09716845 | I47: -0.094730453 | J47: -0.092249707 | K47: -0.09716845 | L47: -0.09716845 | M47: -0.094730453 | N47: -0.0995671 | O47: 0.0099056837 | P47: -0.018202658 | Q47: 0.013078825 | R47: -0.021168819 | S47: -0.033906577 | T47: -0.0066657101 | U47: -0.00026535704
A48: Month = Dec | B48: 0.055766305 | C48: -0.0010262712 | D48: -0.087768516 | E48: -0.092249707 | F48: 1 | G48: -0.085470085 | H48: -0.09002734 | I48: -0.087768516 | J48: -0.085470085 | K48: -0.09002734 | L48: -0.09002734 | M48: -0.087768516 | N48: -0.092249707 | O48: -0.003423032 | P48: 0.039078758 | Q48: -0.00057465072 | R48: -0.037064972 | S48: -0.0015455367 | T48: 0.059185069 | U48: -0.081427309
A49: Month = Feb | B49: -0.071408308 | C49: -0.037787832 | D49: -0.087768516 | E49: -0.092249707 | F49: -0.085470085 | G49: 1 | H49: -0.09002734 | I49: -0.087768516 | J49: -0.085470085 | K49: -0.09002734 | L49: -0.09002734 | M49: -0.087768516 | N49: -0.092249707 | O49: -0.003423032 | P49: 0.0023157782 | Q49: -0.00057465072 | R49: -0.00057465072 | S49: -0.0015455367 | T49: -0.015979969 | U49: 0.062201417
A50: Month = Jan | B50: -0.096870197 | C50: 0.017159801 | D50: -0.092448322 | E50: -0.09716845 | F50: -0.09002734 | G50: -0.09002734 | H50: 1 | I50: -0.092448322 | J50: -0.09002734 | K50: -0.094827586 | L50: -0.094827586 | M50: -0.092448322 | N50: -0.09716845 | O50: -0.017481443 | P50: -0.0116419 | Q50: -0.014582011 | R50: 0.020359789 | S50: -0.039218663 | T50: -0.0096344887 | U50: -0.0032488259
A51: Month = Jul | B51: 0.10058122 | C51: 0.023786049 | D51: -0.090128755 | E51: -0.094730453 | F51: -0.087768516 | G51: -0.087768516 | H51: -0.092448322 | I51: 1 | J51: -0.087768516 | K51: -0.092448322 | L51: -0.092448322 | M51: -0.090128755 | N51: -0.094730453 | O51: -0.010601044 | P51: 0.031141174 | Q51: -0.0077275527 | R51: 0.027959691 | S51: 0.0032119854 | T51: 0.060776652 | U51: -0.076593635
A52: Month = Jun | B52: 0.11050892 | C52: 0.0023156889 | D52: -0.087768516 | E52: -0.092249707 | F52: -0.085470085 | G52: -0.085470085 | H52: -0.09002734 | I52: -0.087768516 | J52: 1 | K52: -0.09002734 | L52: -0.09002734 | M52: -0.087768516 | N52: -0.092249707 | O52: 0.032804057 | P52: 0.0023157782 | Q52: -0.00057465072 | R52: -0.00057465072 | S52: -0.0015455367 | T52: 0.059185069 | U52: 0.062201417
...

Sheet Regression(b..)
A1: StatTools Report
A2: Analysis: | B2: Regression
A3: Performed By: | B3: Baljit Singh
A4: Date: | B4: 45421
A5: Updating: | B5: Static
A6: Variable: | B6: Arrivals
A8: Linearly dependent variables ignored: Month = Sep, Day of week = Wed, Staff payday = Yes, Faculty payday = Yes, After or before holiday = Yes
A10: Multiple Regression for Arrivals | B10: Multiple_x000D_ R | C10: R-Square | D10: Adjusted_x000D_ R-square | E10: Std. Err. of_x000D_ Estimate | F10: Rows_x000D_ Ignored | G10: Outliers
A11: Summary
B12: 0.91229232 | C12: 0.83227728 | D12: 0.80971368 | E12: 148.80656 | F12: 0 | G12: 1
B14: Degrees of_x000D_ Freedom | C14: Sum of_x000D_ Squares | D14: Mean of_x000D_ Squares | E14: F | F14: p-Value
A15: ANOVA Table
A16: Explained | B16: 30 | C16: 24503333 | D16: 816777.76 | E16: 36.885845 | F16: 3.5523411e-70
A17: Unexplained | B17: 223 | C17: 4937976.6 | D17: 22143.393
B19: Coefficient | C19: Standard_x000D_ Error | D19: t-Value | E19: p-Value | F19: Confidence Interval 95% | H19: Multicollinearity Checking
A20: Regression Table | F20: Lower | G20: Upper | H20: VIF | I20: R-Square
A21: Constant | B21: 1858.7151 | C21: 107.74007 | D21: 17.251847 | E21: 6.1749562e-43 | F21: 1646.3962 | G21: 2071.0341
A22: Day of month | B22: -7.0249911 | C22: 4.5328561 | D22: -1.5497936 | E22: 0.12260907 | F22: -15.957705 | G22: 1.9077223 | H22: 18.036199 | I22: 0.94455595
A23: Month = Apr | B23: 73.235029 | C23: 105.17743 | D23: 0.69629984 | E23: 0.48696618 | F23: -134.03382 | G23: 280.50388 | H23: 9.6237084 | I23: 0.89608995
A24: Month = Aug | B24: 312.68846 | C24: 103.2791 | D24: 3.0276063 | E24: 0.002755074 | F24: 109.16057 | G24: 516.21634 | H24: 10.075969 | I24: 0.90075397
A25: Month = Dec | B25: 180.81346 | C25: 108.63799 | D25: 1.6643668 | E25: 0.097443592 | F25: -33.274961 | G25: 394.90188 | H25: 9.82045 | I25: 0.89817167
A26: Month = Feb | B26: 13.992256 | C26: 107.12591 | D26: 0.13061506 | E26: 0.89619758 | F26: -197.11637 | G26: 225.10088 | H26: 9.54898 | I26: 0.89527677
A27: Month = Jan | B27: 45.05768 | C27: 105.1367 | D27: 0.42856281 | E27: 0.66865508 | F27: -162.1309 | G27: 252.24626 | H27: 10.030936 | I27: 0.90030841
A28: Month = Jul | B28: 221.66855 | C28: 106.87316 | D28: 2.0741274 | E28: 0.03921553 | F28: 11.057996 | G28: 432.2791 | H28: 9.9365277 | I28: 0.89936122
A29: Month = Jun | B29: 248.67458 | C29: 107.16047 | D29: 2.3205813 | E29: 0.021212958 | F29: 37.497841 | G29: 459.85132 | H29: 9.5551428 | I29: 0.89534432
A30: Month = Mar | B30: 122.17355 | C30: 104.61711 | D30: 1.1678161 | E30: 0.24412801 | F30: -83.991097 | G30: 328.3382 | H30: 9.9320347 | I30: 0.8993157
A31: Month = May | B31: 114.40052 | C31: 104.18073 | D31: 1.0980968 | E31: 0.27334644 | F31: -90.904159 | G31: 319.7052 | H31: 9.8493493 | I31: 0.89847045
A32: Month = Nov | B32: -8.0491519 | C32: 104.7173 | D32: -0.076865544 | E32: 0.93879943 | F32: -214.41123 | G32: 198.31293 | H32: 9.539688 | I32: 0.89517477
A33: Month = Oct | B33: 7.5535966 | C33: 101.86754 | D33: 0.074151163 | E33: 0.94095658 | F33: -193.19259 | G33: 208.29978 | H33: 9.8024261 | I33: 0.89798444
... A51: Month (Oct) * Day of month | B51: 1.549388 | C51: 5.6478725 | D51: 0.27433126 | E51: 0.78408402 | F51: -9.5806426 | G51: 12.679419 | H51: 10.230381 | I51: 0.90225193
A54: Correlation Matrix | B54: Arrivals | C54: Day of month | D54: Month = Apr | E54: Month = Aug | F54: Month = Dec | G54: Month = Feb | H54: Month = Jan | I54: Month = Jul | J54: Month = Jun | K54: Month = Mar | L54: Month = May | M54: Month = Nov | N54: Month = Oct | O54: Day of week = Fri | P54: Day of week = Mon | Q54: Day of week = Thu | R54: Day of week = Tue | S54: Staff payday = No | T54: Faculty payday = No | U54: After or before holiday = No | V54: Month (Apr) * Day of month | W54: Month (Aug) * Day of month | X54: Month (Dec) * Day of month | Y54: Month (Feb) * Day of month | Z54: Month (Jan) * Day of month | AA54: Month (Jul) * Day of month | AB54: Month (Jun) * Day of month | AC54: Month (Mar) * Day of month | AD54: Month (May) * Day of month | AE54: Month (Nov) * Day of month | AF54: Month (Oct) * Day of month
A55: Arrivals | B55: 1 | C55: -0.25239861 | D55: -0.021275114 | E55: 0.038294619 | F55: 0.055766305 | G55: -0.071408308 | H55: -0.096870197 | I55: 0.10058122 | J55: 0.11050892 | K55: -0.007900887 | L55: 0.065774253 | M55: -0.014934554 | N55: -0.07070768 | O55: 0.68760351 | P55: 0.081013603 | Q55: -0.22290995 | R55: -0.24129838 | S55: -0.64806542 | T55: -0.34547262 | U55: -0.22158964 | V55: -0.026293654 | W55: -0.021359597 | X55: 0.036063409 | Y55: -0.12065221 | Z55: -0.16353924 | AA55: 0.03687028 | AB55: 0.05546264 | AC55: -0.054006267 | AD55: 0.028907681 | AE55: -0.027103642 | AF55: -0.093393225
A56: Day of month | B56: -0.25239861 | C56: 1 | D56: -0.020337491 | E56: 0.018652682 | F56: -0.0010262712 | G56: -0.037787832 | H56: 0.017159801 | I56: 0.023786049 | J56: 0.0023156889 | K56: 0.0075593837 | L56: -0.01324152 | M56: -0.0023612335 | N56: -0.006439837 | O56: 0.0008958046 | P56: 0.0061851446 | Q56: -0.029621542 | R56: -0.013892977 | S56: 0.044973011 | T56: 0.11410604 | U56: -0.041704908 | V56: 0.12109886 | W56: 0.17905831 | X56: 0.12982184 | Y56: 0.098373836 | Z56: 0.16405699 | AA56: 0.15798161 | AB56: 0.13797802 | AC56: 0.15596041 | AD56: 0.15051487 | AE56: 0.14889735 | AF56: 0.16281585
A57: Month = Apr | B57: -0.021275114 | C57: -0.020337491 | D57: 1 | E57: -0.094730453 | F57: -0.087768516 | G57: -0.087768516 | H57: -0.092448322 | I57: -0.090128755 | J57: -0.087768516 | K57: -0.092448322 | L57: -0.092448322 | M57: -0.090128755 | N57: -0.094730453 | O57: -0.010601044 | P57: 0.031141174 | Q57: -0.0077275527 | R57: -0.0077275527 | S57: 0.0032119854 | T57: 0.060776652 | U57: 0.063874115 | V57: 0.86582248 | W57: -0.08141966 | X57: -0.076764627 | Y57: -0.075973758 | Z57: -0.080236171 | AA57: -0.079028936 | AB57: -0.076422422 | AC57: -0.080025084 | AD57: -0.078616137 | AE57: -0.077458092 | AF57: -0.08047004
A58: Month = Aug | B58: 0.038294619 | C58: 0.018652682 | D58: -0.094730453 | E58: 1 | F58: -0.092249707 | G58: -0.092249707 | H58: -0.09716845 | I58: -0.094730453 | J58: -0.092249707 | K58: -0.09716845 | L58: -0.09716845 | M58: -0.094730453 | N58: -0.0995671 | O58: 0.0099056837 | P58: -0.018202658 | Q58: 0.013078825 | R58: -0.021168819 | S58: -0.033906577 | T58: -0.0066657101 | U58: -0.00026535704 | V58: -0.082019756 | W58: 0.8594877 | X58: -0.080683993 | Y58: -0.079852745 | Z58: -0.084332784 | AA58: -0.083063911 | AB58: -0.080324317 | AC58: -0.08411092 | AD58: -0.082630036 | AE58: -0.081412865 | AF58: -0.084578594
A59: Month = Dec | B59: 0.055766305 | C59: -0.0010262712 | D59: -0.087768516 | E59: -0.092249707 | F59: 1 | G59: -0.085470085 | H59: -0.09002734 | I59: -0.087768516 | J59: -0.085470085 | K59: -0.09002734 | L59: -0.09002734 | M59: -0.087768516 | N59: -0.092249707 | O59: -0.003423032 | P59: 0.039078758 | Q59: -0.00057465072 | R59: -0.037064972 | S59: -0.0015455367 | T59: 0.059185069 | U59: -0.081427309 | V59: -0.075991955 | W59: -0.079287489 | X59: 0.87462601 | Y59: -0.073984202 | Z59: -0.078134993 | AA59: -0.076959372 | AB59: -0.074421116 | AC59: -0.077929434 | AD59: -0.076557384 | AE59: -0.075429665 | AF59: -0.078362738
A60: Month = Feb | B60: -0.071408308 | C60: -0.037787832 | D60: -0.087768516 | E60: -0.092249707 | F60: -0.085470085 | G60: 1 | H60: -0.09002734 | I60: -0.087768516 | J60: -0.085470085 | K60: -0.09002734 | L60: -0.09002734 | M60: -0.087768516 | N60: -0.092249707 | O60: -0.003423032 | P60: 0.0023157782 | Q60: -0.00057465072 | R60: -0.00057465072 | S60: -0.0015455367 | T60: -0.015979969 | U60: 0.062201417 | V60: -0.075991955 | W60: -0.079287489 | X60: -0.07475436 | Y60: 0.86561516 | Z60: -0.078134993 | AA60: -0.076959372 | AB60: -0.074421116 | AC60: -0.077929434 | AD60: -0.076557384 | AE60: -0.075429665 | AF60: -0.078362738
A61: Month = Jan | B61: -0.096870197 | C61: 0.017159801 | D61: -0.092448322 | E61: -0.09716845 | F61: -0.09002734 | G61: -0.09002734 | H61: 1 | I61: -0.092448322 | J61: -0.09002734 | K61: -0.094827586 | L61: -0.094827586 | M61: -0.092448322 | N61: -0.09716845 | O61: -0.017481443 | P61: -0.0116419 | Q61: -0.014582011 | R61: 0.020359789 | S61: -0.039218663 | T61: -0.0096344887 | U61: -0.0032488259 | V61: -0.080043836 | W61: -0.083515088 | X61: -0.078740253 | Y61: -0.07792903 | Z61: 0.86790294 | AA61: -0.081062836 | AB61: -0.078389241 | AC61: -0.082084622 | AD61: -0.080639414 | AE61: -0.079451565 | AF61: -0.082541029
A62: Month = Jul | B62: 0.10058122 | C62: 0.023786049 | D62: -0.090128755 | E62: -0.094730453 | F62: -0.087768516 | G62: -0.087768516 | H62: -0.092448322 | I62: 1 | J62: -0.087768516 | K62: -0.092448322 | L62: -0.092448322 | M62: -0.090128755 | N62: -0.094730453 | O62: -0.010601044 | P62: 0.031141174 | Q62: -0.0077275527 | R62: 0.027959691 | S62: 0.0032119854 | T62: 0.060776652 | U62: -0.076593635 | V62: -0.078035503 | W62: -0.08141966 | X62: -0.076764627 | Y62: -0.075973758 | Z62: -0.080236171 | AA62: 0.87684486 | AB62: -0.076422422 | AC62: -0.080025084 | AD62: -0.078616137 | AE62: -0.077458092 | AF62: -0.08047004
A63: Month = Jun | B63: 0.11050892 | C63: 0.0023156889 | D63: -0.087768516 | E63: -0.092249707 | F63: -0.085470085 | G63: -0.085470085 | H63: -0.09002734 | I63: -0.087768516 | J63: 1 | K63: -0.09002734 | L63: -0.09002734 | M63: -0.087768516 | N63: -0.092249707 | O63: 0.032804057 | P63: 0.0023157782 | Q63: -0.00057465072 | R63: -0.00057465072 | S63: -0.0015455367 | T63: 0.059185069 | U63: 0.062201417 | V63: -0.075991955 | W63: -0.079287489 | X63: -0.07475436 | Y63: -0.073984202 | Z63: -0.078134993 | AA63: -0.076959372 | AB63: 0.87072706 | AC63: -0.077929434 | AD63: -0.076557384 | AE63: -0.075429665 | AF63: -0.078362738
...
